Workbook

Sheet Capa

Sheet Uniformidade dados
A1: Vão | B1: ID do | C1: volume (ml) | G1: Média | H1: Distância | I1: Lâm. Média Ponderada | J1: Lam. Projeto | K1: Lâmina (mm) | L1: Lâmina | M1: Lâmina | N1: Si . | Li - Lmp| | O1: Àrea corespondente Ai (ha) | P1: Resultados
A2: Nº | B2: Coletor (Si) | C2: A | D2: B | E2: C | F2: D | L2: média (Li) mm | M2: ponderada (Li . Si) mm
A3: 1º | B3: 1 | C3: 0 | D3: 0 | E3: 0 | F3: 0 | G3: =(C3+D3+E3+F3)/4 -> 0 | H3: 5 | I3: =$P$6 -> 5.8286923 | J3: =$P$21 -> 6.5637 | K3: =(G3/78.54*10) -> 0 | L3: =K3 -> 0 | M3: =B3*L3 -> 0 | N3: =B3*(ABS(L3-$P$6)) -> 5.8286923 | O3: =(3.1416*(H3^2))/10000 -> 0.007854
A4: 1º | B4: 2 | C4: 25 | D4: 25 | E4: 25 | F4: 25 | G4: =(C4+D4+E4+F4)/4 -> 25 | H4: 10 | I4: =$P$6 -> 5.8286923 | J4: =$P$21 -> 6.5637 | K4: =(G4/78.54*10) -> 3.1830914 | L4: =K4 -> 3.1830914 | M4: =B4*L4 -> 6.3661828 | N4: =B4*(ABS(L4-$P$6)) -> 5.2912018 | O4: =(3.1416*(H4^2))/10000 -> 0.031416
A5: 1º | B5: 3 | C5: 60 | D5: 50 | E5: 45 | F5: 40 | G5: =(C5+D5+E5+F5)/4 -> 48.75 | H5: 15 | I5: =$P$6 -> 5.8286923 | J5: =$P$21 -> 6.5637 | K5: =(G5/78.54*10) -> 6.2070283 | L5: =K5 -> 6.2070283 | M5: =B5*L5 -> 18.621085 | N5: =B5*(ABS(L5-$P$6)) -> 1.1350079 | O5: =(3.1416*(H5^2))/10000 -> 0.070686 | P5: Lmp
A6: 1º | B6: 4 | C6: 50 | D6: 45 | E6: 40 | F6: 35 | G6: =(C6+D6+E6+F6)/4 -> 42.5 | H6: 20 | I6: =$P$6 -> 5.8286923 | J6: =$P$21 -> 6.5637 | K6: =(G6/78.54*10) -> 5.4112554 | L6: =K6 -> 5.4112554 | M6: =B6*L6 -> 21.645022 | N6: =B6*(ABS(L6-$P$6)) -> 1.6697476 | O6: =(3.1416*(H6^2))/10000 -> 0.125664 | P6: =(M83/B83) -> 5.8286923
A7: 1º | B7: 5 | C7: 45 | D7: 45 | E7: 40 | F7: 35 | G7: =(C7+D7+E7+F7)/4 -> 41.25 | H7: 25 | I7: =$P$6 -> 5.8286923 | J7: =$P$21 -> 6.5637 | K7: =(G7/78.54*10) -> 5.2521008 | L7: =K7 -> 5.2521008 | M7: =B7*L7 -> 26.260504 | N7: =B7*(ABS(L7-$P$6)) -> 2.8829573 | O7: =(3.1416*(H7^2))/10000 -> 0.19635
A8: 1º | B8: 6 | C8: 50 | D8: 50 | E8: 40 | F8: 40 | G8: =(C8+D8+E8+F8)/4 -> 45 | H8: 30 | I8: =$P$6 -> 5.8286923 | J8: =$P$21 -> 6.5637 | K8: =(G8/78.54*10) -> 5.7295646 | L8: =K8 -> 5.7295646 | M8: =B8*L8 -> 34.377387 | N8: =B8*(ABS(L8-$P$6)) -> 0.59476653 | O8: =(3.1416*(H8^2))/10000 -> 0.282744 | P8: LP25
A9: 1º | B9: 7 | C9: 40 | D9: 40 | E9: 35 | F9: 35 | G9: =(C9+D9+E9+F9)/4 -> 37.5 | H9: 35 | I9: =$P$6 -> 5.8286923 | J9: =$P$21 -> 6.5637 | K9: =(G9/78.54*10) -> 4.7746371 | L9: =K9 -> 4.7746371 | M9: =B9*L9 -> 33.42246 | N9: =B9*(ABS(L9-$P$6)) -> 7.3783863 | O9: =(3.1416*(H9^2))/10000 -> 0.384846 | P9: {=AVERAGE(SMALL(L3:L82,_xlfn.SEQUENCE(ROUNDUP(COUNT(L3:L82)*0.25,0))))} -> 3.8515406
A10: 1º | B10: 8 | C10: 35 | D10: 35 | E10: 35 | F10: 35 | G10: =(C10+D10+E10+F10)/4 -> 35 | H10: 40 | I10: =$P$6 -> 5.8286923 | J10: =$P$21 -> 6.5637 | K10: =(G10/78.54*10) -> 4.456328 | L10: =K10 -> 4.456328 | M10: =B10*L10 -> 35.650624 | N10: =B10*(ABS(L10-$P$6)) -> 10.978915 | O10: =(3.1416*(H10^2))/10000 -> 0.502656
A11: 1º | B11: 9 | C11: 50 | D11: 50 | E11: 45 | F11: 50 | G11: =(C11+D11+E11+F11)/4 -> 48.75 | H11: 45 | I11: =$P$6 -> 5.8286923 | J11: =$P$21 -> 6.5637 | K11: =(G11/78.54*10) -> 6.2070283 | L11: =K11 -> 6.2070283 | M11: =B11*L11 -> 55.863254 | N11: =B11*(ABS(L11-$P$6)) -> 3.4050236 | O11: =(3.1416*(H11^2))/10000 -> 0.636174 | P11: CUC (%)
A12: 1º | B12: 10 | C12: 40 | D12: 40 | E12: 40 | F12: 40 | G12: =(C12+D12+E12+F12)/4 -> 40 | H12: 50 | I12: =$P$6 -> 5.8286923 | J12: =$P$21 -> 6.5637 | K12: =(G12/78.54*10) -> 5.0929463 | L12: =K12 -> 5.0929463 | M12: =B12*L12 -> 50.929463 | N12: =B12*(ABS(L12-$P$6)) -> 7.3574604 | O12: =(3.1416*(H12^2))/10000 -> 0.7854 | P12: =(1-(N83/(P6*B83)))*100 -> 77.484376
A13: 2º | B13: 11 | C13: 40 | D13: 40 | E13: 35 | F13: 35 | G13: =(C13+D13+E13+F13)/4 -> 37.5 | H13: 55 | I13: =$P$6 -> 5.8286923 | J13: =$P$21 -> 6.5637 | K13: =(G13/78.54*10) -> 4.7746371 | L13: =K13 -> 4.7746371 | M13: =B13*L13 -> 52.521008 | N13: =B13*(ABS(L13-$P$6)) -> 11.594607 | O13: =(3.1416*(H13^2))/10000 -> 0.950334
A14: 2º | B14: 12 | C14: 40 | D14: 40 | E14: 40 | F14: 40 | G14: =(C14+D14+E14+F14)/4 -> 40 | H14: 60 | I14: =$P$6 -> 5.8286923 | J14: =$P$21 -> 6.5637 | K14: =(G14/78.54*10) -> 5.0929463 | L14: =K14 -> 5.0929463 | M14: =B14*L14 -> 61.115355 | N14: =B14*(ABS(L14-$P$6)) -> 8.8289525 | O14: =(3.1416*(H14^2))/10000 -> 1.130976 | P14: UD (%)
A15: 2º | B15: 13 | C15: 35 | D15: 35 | E15: 45 | F15: 45 | G15: =(C15+D15+E15+F15)/4 -> 40 | H15: 65 | I15: =$P$6 -> 5.8286923 | J15: =$P$21 -> 6.5637 | K15: =(G15/78.54*10) -> 5.0929463 | L15: =K15 -> 5.0929463 | M15: =B15*L15 -> 66.208302 | N15: =B15*(ABS(L15-$P$6)) -> 9.5646985 | O15: =(3.1416*(H15^2))/10000 -> 1.327326 | P15: =P9/P6*100 -> 66.078983
A16: 2º | B16: 14 | C16: 40 | D16: 40 | E16: 35 | F16: 35 | G16: =(C16+D16+E16+F16)/4 -> 37.5 | H16: 70 | I16: =$P$6 -> 5.8286923 | J16: =$P$21 -> 6.5637 | K16: =(G16/78.54*10) -> 4.7746371 | L16: =K16 -> 4.7746371 | M16: =B16*L16 -> 66.84492 | N16: =B16*(ABS(L16-$P$6)) -> 14.756773 | O16: =(3.1416*(H16^2))/10000 -> 1.539384
A17: 2º | B17: 15 | C17: 35 | D17: 35 | E17: 35 | F17: 35 | G17: =(C17+D17+E17+F17)/4 -> 35 | H17: 75 | I17: =$P$6 -> 5.8286923 | J17: =$P$21 -> 6.5637 | K17: =(G17/78.54*10) -> 4.456328 | L17: =K17 -> 4.456328 | M17: =B17*L17 -> 66.84492 | N17: =B17*(ABS(L17-$P$6)) -> 20.585465 | O17: =(3.1416*(H17^2))/10000 -> 1.76715 | P17: L. armazenada (mm)
A18: 2º | B18: 16 | C18: 65 | D18: 65 | E18: 50 | F18: 50 | G18: =(C18+D18+E18+F18)/4 -> 57.5 | H18: 80 | I18: =$P$6 -> 5.8286923 | J18: =$P$21 -> 6.5637 | K18: =(G18/78.54*10) -> 7.3211103 | L18: =K18 -> 7.3211103 | M18: =B18*L18 -> 117.13776 | N18: =B18*(ABS(L18-$P$6)) -> 23.878687 | O18: =(3.1416*(H18^2))/10000 -> 2.010624 | P18: 5.57
A19: 2º | B19: 17 | C19: 70 | D19: 65 | E19: 50 | F19: 50 | G19: =(C19+D19+E19+F19)/4 -> 58.75 | H19: 85 | I19: =$P$6 -> 5.8286923 | J19: =$P$21 -> 6.5637 | K19: =(G19/78.54*10) -> 7.4802648 | L19: =K19 -> 7.4802648 | M19: =B19*L19 -> 127.1645 | N19: =B19*(ABS(L19-$P$6)) -> 28.076733 | O19: =(3.1416*(H19^2))/10000 -> 2.269806
A20: 2º | B20: 18 | C20: 45 | D20: 45 | E20: 30 | F20: 30 | G20: =(C20+D20+E20+F20)/4 -> 37.5 | H20: 90 | I20: =$P$6 -> 5.8286923 | J20: =$P$21 -> 6.5637 | K20: =(G20/78.54*10) -> 4.7746371 | L20: =K20 -> 4.7746371 | M20: =B20*L20 -> 85.943468 | N20: =B20*(ABS(L20-$P$6)) -> 18.972993 | O20: =(3.1416*(H20^2))/10000 -> 2.544696 | P20: Lâmina de projeto (mm)
A21: 2º | B21: 19 | C21: 45 | D21: 45 | E21: 40 | F21: 40 | G21: =(C21+D21+E21+F21)/4 -> 42.5 | H21: 95 | I21: =$P$6 -> 5.8286923 | J21: =$P$21 -> 6.5637 | K21: =(G21/78.54*10) -> 5.4112554 | L21: =K21 -> 5.4112554 | M21: =B21*L21 -> 102.81385 | N21: =B21*(ABS(L21-$P$6)) -> 7.931301 | O21: =(3.1416*(H21^2))/10000 -> 2.835294 | P21: ='Tabela de Controle do PC'!E8 -> 6.5637
A22: 2º | B22: 20 | C22: 50 | D22: 50 | E22: 40 | F22: 40 | G22: =(C22+D22+E22+F22)/4 -> 45 | H22: 100 | I22: =$P$6 -> 5.8286923 | J22: =$P$21 -> 6.5637 | K22: =(G22/78.54*10) -> 5.7295646 | L22: =K22 -> 5.7295646 | M22: =B22*L22 -> 114.59129 | N22: =B22*(ABS(L22-$P$6)) -> 1.9825551 | O22: =(3.1416*(H22^2))/10000 -> 3.1416
A23: 2º | B23: 21 | C23: 50 | D23: 50 | E23: 40 | F23: 40 | G23: =(C23+D23+E23+F23)/4 -> 45 | H23: 105 | I23: =$P$6 -> 5.8286923 | J23: =$P$21 -> 6.5637 | K23: =(G23/78.54*10) -> 5.7295646 | L23: =K23 -> 5.7295646 | M23: =B23*L23 -> 120.32086 | N23: =B23*(ABS(L23-$P$6)) -> 2.0816828 | O23: =(3.1416*(H23^2))/10000 -> 3.463614 | P23: Epa (%)
A24: 3º | B24: 22 | C24: 70 | D24: 70 | E24: 30 | F24: 30 | G24: =(C24+D24+E24+F24)/4 -> 50 | H24: 110 | I24: =$P$6 -> 5.8286923 | J24: =$P$21 -> 6.5637 | K24: =(G24/78.54*10) -> 6.3661828 | L24: =K24 -> 6.3661828 | M24: =B24*L24 -> 140.05602 | N24: =B24*(ABS(L24-$P$6)) -> 11.824792 | O24: =(3.1416*(H24^2))/10000 -> 3.801336 | P24: =P6/P21*100 -> 88.80193
A25: 3º | B25: 23 | C25: 50 | D25: 65 | E25: 35 | F25: 45 | G25: =(C25+D25+E25+F25)/4 -> 48.75 | H25: 115 | I25: =$P$6 -> 5.8286923 | J25: =$P$21 -> 6.5637 | K25: =(G25/78.54*10) -> 6.2070283 | L25: =K25 -> 6.2070283 | M25: =B25*L25 -> 142.76165 | N25: =B25*(ABS(L25-$P$6)) -> 8.701727 | O25: =(3.1416*(H25^2))/10000 -> 4.154766
A26: 3º | B26: 24 | C26: 55 | D26: 55 | E26: 45 | F26: 45 | G26: =(C26+D26+E26+F26)/4 -> 50 | H26: 120 | I26: =$P$6 -> 5.8286923 | J26: =$P$21 -> 6.5637 | K26: =(G26/78.54*10) -> 6.3661828 | L26: =K26 -> 6.3661828 | M26: =B26*L26 -> 152.78839 | N26: =B26*(ABS(L26-$P$6)) -> 12.899773 | O26: =(3.1416*(H26^2))/10000 -> 4.523904 | P26: Evaporação no ensaio (mm)
A27: 3º | B27: 25 | C27: 55 | D27: 50 | E27: 45 | F27: 45 | G27: =(C27+D27+E27+F27)/4 -> 48.75 | H27: 125 | I27: =$P$6 -> 5.8286923 | J27: =$P$21 -> 6.5637 | K27: =(G27/78.54*10) -> 6.2070283 | L27: =K27 -> 6.2070283 | M27: =B27*L27 -> 155.17571 | N27: =B27*(ABS(L27-$P$6)) -> 9.458399 | O27: =(3.1416*(H27^2))/10000 -> 4.90875 | P27: 1.81
A28: 3º | B28: 26 | C28: 55 | D28: 55 | E28: 25 | F28: 30 | G28: =(C28+D28+E28+F28)/4 -> 41.25 | H28: 130 | I28: =$P$6 -> 5.8286923 | J28: =$P$21 -> 6.5637 | K28: =(G28/78.54*10) -> 5.2521008 | L28: =K28 -> 5.2521008 | M28: =B28*L28 -> 136.55462 | N28: =B28*(ABS(L28-$P$6)) -> 14.991378 | O28: =(3.1416*(H28^2))/10000 -> 5.309304
A29: 3º | B29: 27 | C29: 65 | D29: 65 | E29: 60 | F29: 65 | G29: =(C29+D29+E29+F29)/4 -> 63.75 | H29: 135 | I29: =$P$6 -> 5.8286923 | J29: =$P$21 -> 6.5637 | K29: =(G29/78.54*10) -> 8.1168831 | L29: =K29 -> 8.1168831 | M29: =B29*L29 -> 219.15584 | N29: =B29*(ABS(L29-$P$6)) -> 61.781152 | O29: =(3.1416*(H29^2))/10000 -> 5.725566
A30: 3º | B30: 28 | C30: 50 | D30: 50 | E30: 40 | F30: 40 | G30: =(C30+D30+E30+F30)/4 -> 45 | H30: 140 | I30: =$P$6 -> 5.8286923 | J30: =$P$21 -> 6.5637 | K30: =(G30/78.54*10) -> 5.7295646 | L30: =K30 -> 5.7295646 | M30: =B30*L30 -> 160.42781 | N30: =B30*(ABS(L30-$P$6)) -> 2.7755771 | O30: =(3.1416*(H30^2))/10000 -> 6.157536
A31: 3º | B31: 29 | C31: 80 | D31: 175 | E31: 75 | F31: 75 | G31: =(C31+D31+E31+F31)/4 -> 101.25 | H31: 145 | I31: =$P$6 -> 5.8286923 | J31: =$P$21 -> 6.5637 | K31: =(G31/78.54*10) -> 12.89152 | L31: =K31 -> 12.89152 | M31: =B31*L31 -> 373.85409 | N31: =B31*(ABS(L31-$P$6)) -> 204.82201 | O31: =(3.1416*(H31^2))/10000 -> 6.605214
A32: 3º | B32: 30 | C32: 45 | D32: 45 | E32: 35 | F32: 35 | G32: =(C32+D32+E32+F32)/4 -> 40 | H32: 150 | I32: =$P$6 -> 5.8286923 | J32: =$P$21 -> 6.5637 | K32: =(G32/78.54*10) -> 5.0929463 | L32: =K32 -> 5.0929463 | M32: =B32*L32 -> 152.78839 | N32: =B32*(ABS(L32-$P$6)) -> 22.072381 | O32: =(3.1416*(H32^2))/10000 -> 7.0686
A33: 3º | B33: 31 | C33: 50 | D33: 55 | E33: 45 | F33: 45 | G33: =(C33+D33+E33+F33)/4 -> 48.75 | H33: 155 | I33: =$P$6 -> 5.8286923 | J33: =$P$21 -> 6.5637 | K33: =(G33/78.54*10) -> 6.2070283 | L33: =K33 -> 6.2070283 | M33: =B33*L33 -> 192.41788 | N33: =B33*(ABS(L33-$P$6)) -> 11.728415 | O33: =(3.1416*(H33^2))/10000 -> 7.547694
A34: 4º | B34: 32 | C34: 55 | D34: 55 | E34: 60 | F34: 55 | G34: =(C34+D34+E34+F34)/4 -> 56.25 | H34: 160 | I34: =$P$6 -> 5.8286923 | J34: =$P$21 -> 6.5637 | K34: =(G34/78.54*10) -> 7.1619557 | L34: =K34 -> 7.1619557 | M34: =B34*L34 -> 229.18258 | N34: =B34*(ABS(L34-$P$6)) -> 42.664428 | O34: =(3.1416*(H34^2))/10000 -> 8.042496
A35: 4º | B35: 33 | C35: 60 | D35: 60 | E35: 35 | F35: 35 | G35: =(C35+D35+E35+F35)/4 -> 47.5 | H35: 165 | I35: =$P$6 -> 5.8286923 | J35: =$P$21 -> 6.5637 | K35: =(G35/78.54*10) -> 6.0478737 | L35: =K35 -> 6.0478737 | M35: =B35*L35 -> 199.57983 | N35: =B35*(ABS(L35-$P$6)) -> 7.2329858 | O35: =(3.1416*(H35^2))/10000 -> 8.553006
A36: 4º | B36: 34 | C36: 80 | D36: 80 | E36: 65 | F36: 60 | G36: =(C36+D36+E36+F36)/4 -> 71.25 | H36: 170 | I36: =$P$6 -> 5.8286923 | J36: =$P$21 -> 6.5637 | K36: =(G36/78.54*10) -> 9.0718105 | L36: =K36 -> 9.0718105 | M36: =B36*L36 -> 308.44156 | N36: =B36*(ABS(L36-$P$6)) -> 110.26602 | O36: =(3.1416*(H36^2))/10000 -> 9.079224
A37: 4º | B37: 35 | C37: 50 | D37: 50 | E37: 35 | F37: 35 | G37: =(C37+D37+E37+F37)/4 -> 42.5 | H37: 175 | I37: =$P$6 -> 5.8286923 | J37: =$P$21 -> 6.5637 | K37: =(G37/78.54*10) -> 5.4112554 | L37: =K37 -> 5.4112554 | M37: =B37*L37 -> 189.39394 | N37: =B37*(ABS(L37-$P$6)) -> 14.610291 | O37: =(3.1416*(H37^2))/10000 -> 9.62115
A38: 4º | B38: 36 | C38: 55 | D38: 50 | E38: 40 | F38: 40 | G38: =(C38+D38+E38+F38)/4 -> 46.25 | H38: 180 | I38: =$P$6 -> 5.8286923 | J38: =$P$21 -> 6.5637 | K38: =(G38/78.54*10) -> 5.8887191 | L38: =K38 -> 5.8887191 | M38: =B38*L38 -> 211.99389 | N38: =B38*(ABS(L38-$P$6)) -> 2.1609654 | O38: =(3.1416*(H38^2))/10000 -> 10.178784
A39: 4º | B39: 37 | C39: 75 | D39: 85 | E39: 60 | F39: 65 | G39: =(C39+D39+E39+F39)/4 -> 71.25 | H39: 185 | I39: =$P$6 -> 5.8286923 | J39: =$P$21 -> 6.5637 | K39: =(G39/78.54*10) -> 9.0718105 | L39: =K39 -> 9.0718105 | M39: =B39*L39 -> 335.65699 | N39: =B39*(ABS(L39-$P$6)) -> 119.99537 | O39: =(3.1416*(H39^2))/10000 -> 10.752126
... A82: b | B82: 80 | C82: 50 | D82: 50 | E82: 0 | F82: 0 | G82: =(C82+D82+E82+F82)/4 -> 25 | H82: 400 | I82: =$P$6 -> 5.8286923 | J82: =$P$21 -> 6.5637 | K82: =(G82/78.54*10) -> 3.1830914 | L82: =K82 -> 3.1830914 | M82: =B82*L82 -> 254.64731 | N82: =B82*(ABS(L82-$P$6)) -> 211.64807 | O82: =(3.1416*(H82^2))/10000 -> 50.2656
...

Sheet Hidro dados
A1: Nº do bico | B1: Tempo (s) | C1: Volume (l) | D1: Vazão lida (m3/h) | E1: Vazão lida (m3/h) | F1: Pressão 1 (kg/cm2) | G1: D do bocal (mm) | I1: COMO ESTÁ HOJE | K1: COMO FICA DEPOIS DO REMANEJAMENTO DE BOCAIS | N1: ANTES | O1: DEPOIS | P1: DEPOIS | Q1: ANTES
A2: 1 | B2: 10.19 | C2: 1 | D2: =C2/B2*3.6 -> 0.35328754 | E2: =SUM(AVERAGE($D$2:$D$146)) -> 2.4214181 | F2: 3.8 | G2: 7 | I2: Vazão lida (m3/h) | J2: Nº do bico na sequencia atual | K2: Vazão lida (m3/h) | L2: Nº do bico depois da realocação | M2: Média | N2: Nº do bico na sequencia atual | O2: Nº do bico na sequencia atual | P2: D do bocal depois | Q2: D do bocal antes
A3: 2 | B3: 10.39 | C3: 1.5 | D3: =C3/B3*3.6 -> 0.51973051 | E3: =SUM(AVERAGE($D$2:$D$146)) -> 2.4214181 | F3: 4 | G3: 8.5 | I3: 0.35328754 | J3: 1 | K3: 0.35328754 | L3: 1 | M3: 2.38 | N3: 1 | O3: 1 | P3: 7 | Q3: 7
A4: 3 | B4: 10.13 | C4: 1.9 | D4: =C4/B4*3.6 -> 0.67522211 | E4: =SUM(AVERAGE($D$2:$D$146)) -> 2.4214181 | F4: 3.9 | G4: 10 | I4: 0.51973051 | J4: 2 | K4: 0.51973051 | L4: 2 | M4: 2.38 | N4: 2 | O4: 2 | P4: 8.5 | Q4: 8.5
A5: 4 | B5: 10.32 | C5: 2.3 | D5: =C5/B5*3.6 -> 0.80232558 | E5: =SUM(AVERAGE($D$2:$D$146)) -> 2.4214181 | F5: 3.8 | G5: 11 | I5: 0.67522211 | J5: 3 | K5: 0.67522211 | L5: 3 | M5: 2.38 | N5: 3 | O5: 3 | P5: 10 | Q5: 10
A6: 5 | B6: 10.32 | C6: 2.65 | D6: =C6/B6*3.6 -> 0.9244186 | E6: =SUM(AVERAGE($D$2:$D$146)) -> 2.4214181 | F6: 3.8 | G6: 12.5 | I6: 0.80232558 | J6: 4 | K6: 0.80232558 | L6: 4 | M6: 2.38 | N6: 4 | O6: 4 | P6: 11 | Q6: 11
A7: 6 | B7: 10.32 | C7: 3.25 | D7: =C7/B7*3.6 -> 1.1337209 | E7: =SUM(AVERAGE($D$2:$D$146)) -> 2.4214181 | F7: 3.7 | G7: 13 | I7: 0.9244186 | J7: 5 | K7: 0.9244186 | L7: 5 | M7: 2.38 | N7: 5 | O7: 5 | P7: 12.5 | Q7: 12.5
A8: 7 | B8: 10.26 | C8: 3.05 | D8: =C8/B8*3.6 -> 1.0701754 | E8: =SUM(AVERAGE($D$2:$D$146)) -> 2.4214181 | F8: 3.7 | G8: 14 | I8: 1.1337209 | J8: 6 | K8: 1.0701754 | L8: 7 | M8: 2.38 | N8: 6 | O8: 6 | P8: 13 | Q8: 13
A9: 8 | B9: 10.46 | C9: 4.15 | D9: =C9/B9*3.6 -> 1.4282983 | E9: =SUM(AVERAGE($D$2:$D$146)) -> 2.4214181 | F9: 3.6 | G9: 15 | I9: 1.0701754 | J9: 7 | K9: 1.1337209 | L9: 6 | M9: 2.38 | N9: 7 | O9: 7 | P9: 14 | Q9: 14
A10: 9 | B10: 10.45 | C10: 5 | D10: =C10/B10*3.6 -> 1.722488 | E10: =SUM(AVERAGE($D$2:$D$146)) -> 2.4214181 | F10: 3.4 | G10: 16 | I10: 1.4282983 | J10: 8 | K10: 1.3591481 | L10: 11 | M10: 2.38 | N10: 8 | O10: 8 | P10: 15 | Q10: 15
A11: 10 | B11: 10.25 | C11: 4.8 | D11: =C11/B11*3.6 -> 1.6858537 | E11: =SUM(AVERAGE($D$2:$D$146)) -> 2.4214181 | F11: 3.4 | G11: 17 | I11: 1.722488 | J11: 9 | K11: 1.4282983 | L11: 8 | M11: 2.38 | N11: 9 | O11: 18 | P11: 15.5 | Q11: 16
A12: 11 | B12: 10.33 | C12: 3.9 | D12: =C12/B12*3.6 -> 1.3591481 | E12: =SUM(AVERAGE($D$2:$D$146)) -> 2.4214181 | F12: 3.3 | G12: 17.5 | I12: 1.6858537 | J12: 10 | K12: 1.4883268 | L12: 92 | M12: 2.38 | N12: 10 | O12: 19 | P12: 15.5 | Q12: 17
A13: 12 | B13: 10.31 | C13: 6.3 | D13: =C13/B13*3.6 -> 2.199806 | E13: =SUM(AVERAGE($D$2:$D$146)) -> 2.4214181 | F13: 3.3 | G13: 18.5 | I13: 1.3591481 | J13: 11 | K13: 1.5458015 | L13: 18 | M13: 2.38 | N13: 11 | O13: 9 | P13: 16 | Q13: 17.5
A14: 13 | B14: 10.58 | C14: 7.6 | D14: =C14/B14*3.6 -> 2.5860113 | E14: =SUM(AVERAGE($D$2:$D$146)) -> 2.4214181 | F14: 3.2 | G14: 19 | I14: 2.199806 | J14: 12 | K14: 1.5667311 | L14: 19 | M14: 2.38 | N14: 12 | O14: 20 | P14: 16 | Q14: 18.5
... A145: 144 | B145: 10.6 | C145: 5.1 | D145: =C145/B145*3.6 -> 1.7320755 | E145: =SUM(AVERAGE($D$2:$D$146)) -> 2.4214181 | F145: 1.2 | G145: 21 | I145: 2.4797688 | J145: 143 | K145: 4.0701754 | L145: 68 | M145: 2.38 | N145: 143 | O145: 80 | P145: 26 | Q145: 21
A146: 145 | B146: 10.73 | C146: 24.3 | D146: =C146/B146*3.6 -> 8.1528425 | I146: 1.7320755 | J146: 144 | K146: 4.1484375 | L146: 71 | M146: 2.38 | N146: 144 | O146: 81 | P146: 26 | Q146: 21
D147: =SUM(D2:D146) -> 351.10562

Sheet Adequabilidade dados
A1: ADEQUABILIDADE DA IRRIGAÇÃO
A2: Frequencia acumulada | B2: Lâminas | C2: Lamina de projeto | D2: Lamina Média Ponderada
A3: 1.25 | B3: 13.21 | C3: ='Tabela de Controle do PC'!$E$8 -> 6.5637 | D3: ='Uniformidade dados'!$P$6 -> 5.8286923
A4: 2.5 | B4: 12.89 | C4: ='Tabela de Controle do PC'!$E$8 -> 6.5637 | D4: ='Uniformidade dados'!$P$6 -> 5.8286923
A5: 3.75 | B5: 10.03 | C5: ='Tabela de Controle do PC'!$E$8 -> 6.5637 | D5: ='Uniformidade dados'!$P$6 -> 5.8286923
A6: 6.25 | B6: 9.07 | C6: ='Tabela de Controle do PC'!$E$8 -> 6.5637 | D6: ='Uniformidade dados'!$P$6 -> 5.8286923
A7: 7.5 | B7: 8.59 | C7: ='Tabela de Controle do PC'!$E$8 -> 6.5637 | D7: ='Uniformidade dados'!$P$6 -> 5.8286923
A8: 8.75 | B8: 8.12 | C8: ='Tabela de Controle do PC'!$E$8 -> 6.5637 | D8: ='Uniformidade dados'!$P$6 -> 5.8286923
A9: 10 | B9: 7.96 | C9: ='Tabela de Controle do PC'!$E$8 -> 6.5637 | D9: ='Uniformidade dados'!$P$6 -> 5.8286923
A10: 11.25 | B10: 7.64 | C10: ='Tabela de Controle do PC'!$E$8 -> 6.5637 | D10: ='Uniformidade dados'!$P$6 -> 5.8286923
A11: 13.75 | B11: 7.48 | C11: ='Tabela de Controle do PC'!$E$8 -> 6.5637 | D11: ='Uniformidade dados'!$P$6 -> 5.8286923
A12: 15 | B12: 7.32 | C12: ='Tabela de Controle do PC'!$E$8 -> 6.5637 | D12: ='Uniformidade dados'!$P$6 -> 5.8286923
A13: 17.5 | B13: 7.16 | C13: ='Tabela de Controle do PC'!$E$8 -> 6.5637 | D13: ='Uniformidade dados'!$P$6 -> 5.8286923
A14: 18.75 | B14: 7 | C14: ='Tabela de Controle do PC'!$E$8 -> 6.5637 | D14: ='Uniformidade dados'!$P$6 -> 5.8286923
... A35: 100 | B35: 0 | C35: ='Tabela de Controle do PC'!$E$8 -> 6.5637 | D35: ='Uniformidade dados'!$P$6 -> 5.8286923
A37: =A26-A19 -> 38.75 | D37: =100-36.25-38.75 -> 25

Sheet Planilha1

Sheet Tabela de Controle do PC
A1: TABELA DE APLICAÇÃO DE ÁGUA DO PIVÔ AVALIADO
A2: FAZENDA JALAPÃO
A3: Comp.pivô a ultima torre | E3: 374
A4: Vazâo lida | E4: 351
A5: Velocidade | E5: 250
A6: Raio irrigado | E6: 400
A7: Tempo de giro a 100% | E7: =(2*3.1416*E3)/E5 -> 9.3996672
A8: Lâmina bruta a 100% | E8: =(E7*E4)/(10*((3.1416*E6^2)/10000)) -> 6.5637
A9: Pressão de trabalho | E9: 3.8
A10: Eficiência de aplicação | E10: ='Uniformidade dados'!P24 -> 88.80193
A11: CUC | E11: ='Uniformidade dados'!P12 -> 77.484376
A12: Leitura no percentimetro (%) | C12: Velocidade proporcional | D12: Tempo por volta (h) | E12: Lâmina bruta (mm)
A13: 10 | C13: =(A13/100)*$E$5 -> 25 | D13: =($E$7*100)/A13 -> 93.996672 | E13: =($E$8*100)/A13 -> 65.637
A14: 11 | C14: =(A14/100)*$E$5 -> 27.5 | D14: =($E$7*100)/A14 -> 85.45152 | E14: =($E$8*100)/A14 -> 59.67
A15: 12 | C15: =(A15/100)*$E$5 -> 30 | D15: =($E$7*100)/A15 -> 78.33056 | E15: =($E$8*100)/A15 -> 54.6975
A16: 13 | C16: =(A16/100)*$E$5 -> 32.5 | D16: =($E$7*100)/A16 -> 72.305132 | E16: =($E$8*100)/A16 -> 50.49
A17: 14 | C17: =(A17/100)*$E$5 -> 35 | D17: =($E$7*100)/A17 -> 67.14048 | E17: =($E$8*100)/A17 -> 46.883571
A18: 15 | C18: =(A18/100)*$E$5 -> 37.5 | D18: =($E$7*100)/A18 -> 62.664448 | E18: =($E$8*100)/A18 -> 43.758
A19: 16 | C19: =(A19/100)*$E$5 -> 40 | D19: =($E$7*100)/A19 -> 58.74792 | E19: =($E$8*100)/A19 -> 41.023125
A20: 17 | C20: =(A20/100)*$E$5 -> 42.5 | D20: =($E$7*100)/A20 -> 55.29216 | E20: =($E$8*100)/A20 -> 38.61
A21: 18 | C21: =(A21/100)*$E$5 -> 45 | D21: =($E$7*100)/A21 -> 52.220373 | E21: =($E$8*100)/A21 -> 36.465
A22: 19 | C22: =(A22/100)*$E$5 -> 47.5 | D22: =($E$7*100)/A22 -> 49.471933 | E22: =($E$8*100)/A22 -> 34.545789
A23: 20 | C23: =(A23/100)*$E$5 -> 50 | D23: =($E$7*100)/A23 -> 46.998336 | E23: =($E$8*100)/A23 -> 32.8185
A24: 21 | C24: =(A24/100)*$E$5 -> 52.5 | D24: =($E$7*100)/A24 -> 44.76032 | E24: =($E$8*100)/A24 -> 31.255714
... A103: 100 | C103: =(A103/100)*$E$5 -> 250 | D103: =($E$7*100)/A103 -> 9.3996672 | E103: =($E$8*100)/A103 -> 6.5637
